<?xml version="1.0" encoding="utf-8"?>
<!-- This URDF was automatically created by SolidWorks to URDF Exporter! Originally created by Stephen Brawner (brawner@gmail.com) 
     Commit Version: 1.6.0-4-g7f85cfe  Build Version: 1.6.7995.38578
     For more information, please see http://wiki.ros.org/sw_urdf_exporter -->
<robot
  name="car_4ws_4wd">
  <link
    name="base_link">
    <inertial>
      <origin
        xyz="-0.00117586528514695 -4.30552833609457E-17 0.174335815287564"
        rpy="0 0 0" />
      <mass
        value="40.2533565247656" />
      <inertia
        ixx="1.311634309655"
        ixy="1.64735322115376E-16"
        ixz="0.0137789561118299"
        iyy="3.43401128074704"
        iyz="-1.3755764102141E-16"
        izz="3.79965514788602" />
    </inertial>
    <visual>
      <origin
        xyz="0 0 0"
        rpy="0 0 0" />
      <geometry>
        <mesh
          filename="package://car_4ws_4wd/meshes/base_link.STL" />
      </geometry>
      <material
        name="">
        <color
          rgba="0.392156862745098 0.384313725490196 1 1" />
      </material>
    </visual>
    <collision>
      <origin
        xyz="0 0 0"
        rpy="0 0 0" />
      <geometry>
        <mesh
          filename="package://car_4ws_4wd/meshes/base_link.STL" />
      </geometry>
    </collision>
  </link>
  <link
    name="fl_steer_link">
    <inertial>
      <origin
        xyz="5.55111512312578E-17 5.55111512312578E-17 -0.0887276076955047"
        rpy="0 0 0" />
      <mass
        value="10" />
      <inertia
        ixx="0.0479041488909969"
        ixy="4.94445973536415E-18"
        ixz="-1.96308762932002E-18"
        iyy="0.0375622537766457"
        iyz="2.04345079483808E-18"
        izz="0.0141921219001303" />
    </inertial>
    <visual>
      <origin
        xyz="0 0 0"
        rpy="0 0 0" />
      <geometry>
        <mesh
          filename="package://car_4ws_4wd/meshes/fl_steer_link.STL" />
      </geometry>
      <material
        name="">
        <color
          rgba="1 0.96078431372549 0.905882352941176 1" />
      </material>
    </visual>
    <collision>
      <origin
        xyz="0 0 0"
        rpy="0 0 0" />
      <geometry>
        <mesh
          filename="package://car_4ws_4wd/meshes/fl_steer_link.STL" />
      </geometry>
    </collision>
  </link>
  <joint
    name="fl_steer_joint"
    type="revolute">
    <origin
      xyz="0.32 0.235 -0.01"
      rpy="0 0 0" />
    <parent
      link="base_link" />
    <child
      link="fl_steer_link" />
    <axis
      xyz="0 0 -1" />
    <limit
      lower="-0.55"
      upper="0.55"
      effort="100"
      velocity="1" />
  </joint>
  <link
    name="fl_drive_link">
    <inertial>
      <origin
        xyz="5.55111512312578E-17 1.66533453693773E-16 0"
        rpy="0 0 0" />
      <mass
        value="2.16662276325971" />
      <inertia
        ixx="0.0105784924083826"
        ixy="-2.32107504311249E-18"
        ixz="-3.29147472915797E-18"
        iyy="0.0105784924083826"
        iyz="2.86815712206063E-19"
        izz="0.0202757786355256" />
    </inertial>
    <visual>
      <origin
        xyz="0 0 0"
        rpy="0 0 0" />
      <geometry>
        <mesh
          filename="package://car_4ws_4wd/meshes/fl_drive_link.STL" />
      </geometry>
      <material
        name="">
        <color
          rgba="0 0 0 1" />
      </material>
    </visual>
    <collision>
      <origin
        xyz="0 0 0"
        rpy="0 0 0" />
      <geometry>
        <mesh
          filename="package://car_4ws_4wd/meshes/fl_drive_link.STL" />
      </geometry>
    </collision>
  </link>
  <joint
    name="fl_drive_joint"
    type="continuous">
    <origin
      xyz="0 0 -0.16"
      rpy="1.5707963267949 0 0" />
    <parent
      link="fl_steer_link" />
    <child
      link="fl_drive_link" />
    <axis
      xyz="0 0 1" />
  </joint>
  <link
    name="fr_steer_link">
    <inertial>
      <origin
        xyz="-5.55111512312578E-17 2.77555756156289E-17 -0.0887276076955047"
        rpy="0 0 0" />
      <mass
        value="10" />
      <inertia
        ixx="0.0479041488909969"
        ixy="2.72575887867997E-18"
        ixz="-6.24668436201888E-18"
        iyy="0.0375622537766457"
        iyz="6.09446998085633E-18"
        izz="0.0141921219001303" />
    </inertial>
    <visual>
      <origin
        xyz="0 0 0"
        rpy="0 0 0" />
      <geometry>
        <mesh
          filename="package://car_4ws_4wd/meshes/fr_steer_link.STL" />
      </geometry>
      <material
        name="">
        <color
          rgba="1 0.96078431372549 0.905882352941176 1" />
      </material>
    </visual>
    <collision>
      <origin
        xyz="0 0 0"
        rpy="0 0 0" />
      <geometry>
        <mesh
          filename="package://car_4ws_4wd/meshes/fr_steer_link.STL" />
      </geometry>
    </collision>
  </link>
  <joint
    name="fr_steer_joint"
    type="revolute">
    <origin
      xyz="0.32 -0.235 -0.00999999999999999"
      rpy="0 0 0" />
    <parent
      link="base_link" />
    <child
      link="fr_steer_link" />
    <axis
      xyz="0 0 -1" />
    <limit
      lower="-0.55"
      upper="0.55"
      effort="100"
      velocity="1" />
  </joint>
  <link
    name="fr_drive_link">
    <inertial>
      <origin
        xyz="5.55111512312578E-17 1.38777878078145E-16 -5.55111512312578E-17"
        rpy="0 0 0" />
      <mass
        value="2.16662276325971" />
      <inertia
        ixx="0.0105784924083826"
        ixy="-2.21723853185535E-18"
        ixz="-4.05189609818123E-18"
        iyy="0.0105784924083826"
        iyz="3.14161592140784E-18"
        izz="0.0202757786355255" />
    </inertial>
    <visual>
      <origin
        xyz="0 0 0"
        rpy="0 0 0" />
      <geometry>
        <mesh
          filename="package://car_4ws_4wd/meshes/fr_drive_link.STL" />
      </geometry>
      <material
        name="">
        <color
          rgba="0 0 0 1" />
      </material>
    </visual>
    <collision>
      <origin
        xyz="0 0 0"
        rpy="0 0 0" />
      <geometry>
        <mesh
          filename="package://car_4ws_4wd/meshes/fr_drive_link.STL" />
      </geometry>
    </collision>
  </link>
  <joint
    name="fr_drive_joint"
    type="continuous">
    <origin
      xyz="0 0 -0.16"
      rpy="1.5707963267949 0 0" />
    <parent
      link="fr_steer_link" />
    <child
      link="fr_drive_link" />
    <axis
      xyz="0 0 1" />
  </joint>
  <link
    name="rl_steer_link">
    <inertial>
      <origin
        xyz="5.55111512312578E-17 -8.32667268468867E-17 -0.0887276076955047"
        rpy="0 0 0" />
      <mass
        value="10" />
      <inertia
        ixx="0.0479041488909969"
        ixy="-9.86394100270256E-19"
        ixz="1.88993973604895E-17"
        iyy="0.0375622537766457"
        iyz="-3.45987688850248E-17"
        izz="0.0141921219001303" />
    </inertial>
    <visual>
      <origin
        xyz="0 0 0"
        rpy="0 0 0" />
      <geometry>
        <mesh
          filename="package://car_4ws_4wd/meshes/rl_steer_link.STL" />
      </geometry>
      <material
        name="">
        <color
          rgba="1 0.96078431372549 0.905882352941176 1" />
      </material>
    </visual>
    <collision>
      <origin
        xyz="0 0 0"
        rpy="0 0 0" />
      <geometry>
        <mesh
          filename="package://car_4ws_4wd/meshes/rl_steer_link.STL" />
      </geometry>
    </collision>
  </link>
  <joint
    name="rl_steer_joint"
    type="revolute">
    <origin
      xyz="-0.32 0.235 -0.01"
      rpy="0 0 0" />
    <parent
      link="base_link" />
    <child
      link="rl_steer_link" />
    <axis
      xyz="0 0 -1" />
    <limit
      lower="-0.55"
      upper="0.55"
      effort="100"
      velocity="1" />
  </joint>
  <link
    name="rl_drive_link">
    <inertial>
      <origin
        xyz="1.11022302462516E-16 1.38777878078145E-16 -2.77555756156289E-17"
        rpy="0 0 0" />
      <mass
        value="2.16662276325971" />
      <inertia
        ixx="0.0105784924083827"
        ixy="-1.64270547161544E-18"
        ixz="-2.9596986991524E-18"
        iyy="0.0105784924083827"
        iyz="1.29365881677942E-17"
        izz="0.0202757786355256" />
    </inertial>
    <visual>
      <origin
        xyz="0 0 0"
        rpy="0 0 0" />
      <geometry>
        <mesh
          filename="package://car_4ws_4wd/meshes/rl_drive_link.STL" />
      </geometry>
      <material
        name="">
        <color
          rgba="0 0 0 1" />
      </material>
    </visual>
    <collision>
      <origin
        xyz="0 0 0"
        rpy="0 0 0" />
      <geometry>
        <mesh
          filename="package://car_4ws_4wd/meshes/rl_drive_link.STL" />
      </geometry>
    </collision>
  </link>
  <joint
    name="rl_drive_joint"
    type="continuous">
    <origin
      xyz="0 0 -0.16"
      rpy="1.5707963267949 0 0" />
    <parent
      link="rl_steer_link" />
    <child
      link="rl_drive_link" />
    <axis
      xyz="0 0 1" />
  </joint>
  <link
    name="rr_steer_link">
    <inertial>
      <origin
        xyz="0 -2.7756E-17 -0.088728"
        rpy="0 0 0" />
      <mass
        value="10" />
      <inertia
        ixx="0.047904"
        ixy="2.4387E-18"
        ixz="-5.5151E-18"
        iyy="0.037562"
        iyz="-5.8473E-18"
        izz="0.014192" />
    </inertial>
    <visual>
      <origin
        xyz="0 0 0"
        rpy="0 0 0" />
      <geometry>
        <mesh
          filename="package://car_4ws_4wd/meshes/rr_steer_link.STL" />
      </geometry>
      <material
        name="">
        <color
          rgba="1 0.96078 0.90588 1" />
      </material>
    </visual>
    <collision>
      <origin
        xyz="0 0 0"
        rpy="0 0 0" />
      <geometry>
        <mesh
          filename="package://car_4ws_4wd/meshes/rr_steer_link.STL" />
      </geometry>
    </collision>
  </link>
  <joint
    name="rr_steer_joint"
    type="revolute">
    <origin
      xyz="-0.32 -0.235 -0.01"
      rpy="0 0 0" />
    <parent
      link="base_link" />
    <child
      link="rr_steer_link" />
    <axis
      xyz="0 0 -1" />
    <limit
      lower="-0.55"
      upper="0.55"
      effort="100"
      velocity="1" />
  </joint>
  <link
    name="rr_drive_link">
    <inertial>
      <origin
        xyz="5.5511E-17 1.3878E-16 2.7756E-17"
        rpy="0 0 0" />
      <mass
        value="2.1666" />
      <inertia
        ixx="0.010578"
        ixy="-2.5643E-18"
        ixz="-3.6716E-18"
        iyy="0.010578"
        iyz="2.8927E-18"
        izz="0.020276" />
    </inertial>
    <visual>
      <origin
        xyz="0 0 0"
        rpy="0 0 0" />
      <geometry>
        <mesh
          filename="package://car_4ws_4wd/meshes/rr_drive_link.STL" />
      </geometry>
      <material
        name="">
        <color
          rgba="0 0 0 1" />
      </material>
    </visual>
    <collision>
      <origin
        xyz="0 0 0"
        rpy="0 0 0" />
      <geometry>
        <mesh
          filename="package://car_4ws_4wd/meshes/rr_drive_link.STL" />
      </geometry>
    </collision>
  </link>
  <joint
    name="rr_drive_joint"
    type="continuous">
    <origin
      xyz="0 0 -0.16"
      rpy="1.5707963267949 0 0" />
    <parent
      link="rr_steer_link" />
    <child
      link="rr_drive_link" />
    <axis
      xyz="0 0 1" />
  </joint>
  <link
    name="lidar_link">
    <inertial>
      <origin
        xyz="-3.4211E-49 9.7454E-19 1.1102E-16"
        rpy="0 0 0" />
      <mass
        value="0.3927" />
      <inertia
        ixx="0.00032725"
        ixy="9.7388E-52"
        ixz="-6.1103E-36"
        iyy="0.00032725"
        iyz="-3.3795E-35"
        izz="0.00049087" />
    </inertial>
    <visual>
      <origin
        xyz="0 0 0"
        rpy="0 0 0" />
      <geometry>
        <mesh
          filename="package://car_4ws_4wd/meshes/lidar_link.STL" />
      </geometry>
      <material
        name="">
        <color
          rgba="0 0 0 1" />
      </material>
    </visual>
    <collision>
      <origin
        xyz="0 0 0"
        rpy="0 0 0" />
      <geometry>
        <mesh
          filename="package://car_4ws_4wd/meshes/lidar_link.STL" />
      </geometry>
    </collision>
  </link>
  <joint
    name="lidar_joint"
    type="fixed">
    <origin
      xyz="0 0 0.565"
      rpy="0 0 0" />
    <parent
      link="base_link" />
    <child
      link="lidar_link" />
    <axis
      xyz="0 0 0" />
  </joint>
</robot>