<?xml version="1.0" encoding="utf-8"?>
<!-- This URDF was automatically created by SolidWorks to URDF Exporter! Originally created by Stephen Brawner (brawner@gmail.com) 
     Commit Version: 1.6.0-4-g7f85cfe  Build Version: 1.6.7995.38578
     For more information, please see http://wiki.ros.org/sw_urdf_exporter -->

<robot
  name="car_4ws_4wd">
   <!-- dummy link -->
  <link name="base"/>
  <joint name="base_joint" type="fixed">
    <parent link="base"/>
    <child link="base_link"/>
    <origin xyz="0 0 0.3" rpy="0 0 0"/>
  </joint>
  <link
    name="base_link">
    <inertial>
      <origin
        xyz="0.00067927 -4.2592E-17 0.17564"
        rpy="0 0 0" />
      <mass
        value="40.395" />
      <inertia
        ixx="1.3314"
        ixy="1.5345E-16"
        ixz="-0.010988"
        iyy="3.4758"
        iyz="-1.4414E-16"
        izz="3.8221" />
    </inertial>
    <visual>
      <origin
        xyz="0 0 0"
        rpy="0 0 0" />
      <geometry>
        <mesh
          filename="package://car_4ws_4wd/meshes/base_link.STL" />
      </geometry>
      <material
        name="">
        <color
          rgba="0.39216 0.38431 1 1" />
      </material>
    </visual>
    <collision>
      <origin
        xyz="0 0 0"
        rpy="0 0 0" />
      <geometry>
        <mesh
          filename="package://car_4ws_4wd/meshes/base_link.STL" />
      </geometry>
    </collision>
  </link>
  <link
    name="fl_steer_link">
    <inertial>
      <origin
        xyz="0 2.7756E-17 -0.088728"
        rpy="0 0 0" />
      <mass
        value="10" />
      <inertia
        ixx="0.047904"
        ixy="5.0347E-18"
        ixz="-9.6918E-19"
        iyy="0.037562"
        iyz="2.1835E-18"
        izz="0.014192" />
    </inertial>
    <visual>
      <origin
        xyz="0 0 0"
        rpy="0 0 0" />
      <geometry>
        <mesh
          filename="package://car_4ws_4wd/meshes/fl_steer_link.STL" />
      </geometry>
      <material
        name="">
        <color
          rgba="1 0.96078 0.90588 1" />
      </material>
    </visual>
    <collision>
      <origin
        xyz="0 0 0"
        rpy="0 0 0" />
      <geometry>
        <mesh
          filename="package://car_4ws_4wd/meshes/fl_steer_link.STL" />
      </geometry>
    </collision>
  </link>
  <joint
    name="fl_steer_joint"
    type="revolute">
    <origin
      xyz="0.32 0.235 -0.01"
      rpy="0 0 0" />
    <parent
      link="base_link" />
    <child
      link="fl_steer_link" />
    <axis
      xyz="0 0 1" />
    <limit
      lower="-0.55"
      upper="0.55"
      effort="100"
      velocity="1" />
  </joint>
  <link
    name="fl_drive_link">
    <inertial>
      <origin
        xyz="5.5511E-17 1.6653E-16 0"
        rpy="0 0 0" />
      <mass
        value="2.1666" />
      <inertia
        ixx="0.010578"
        ixy="-2.3208E-18"
        ixz="-3.2911E-18"
        iyy="0.010578"
        iyz="2.8693E-19"
        izz="0.020276" />
    </inertial>
    <visual>
      <origin
        xyz="0 0 0"
        rpy="0 0 0" />
      <geometry>
        <mesh
          filename="package://car_4ws_4wd/meshes/fl_drive_link.STL" />
      </geometry>
      <material
        name="">
        <color
          rgba="0 0 0 1" />
      </material>
    </visual>
    <collision>
      <origin
        xyz="0 0 0"
        rpy="0 0 0" />
      <geometry>
        <mesh
          filename="package://car_4ws_4wd/meshes/fl_drive_link.STL" />
      </geometry>
    </collision>
  </link>
  <joint
    name="fl_drive_joint"
    type="continuous">
    <origin
      xyz="0 0 -0.16"
      rpy="1.5708 0 0" />
    <parent
      link="fl_steer_link" />
    <child
      link="fl_drive_link" />
    <axis
      xyz="0 0 -1" />
  </joint>
  <gazebo reference="fl_drive_link">
    <mu1>1.0</mu1>
    <mu2>1.0</mu2>
    <kp>1000000.0</kp>
    <kd>100.0</kd>
    <minDepth>0.001</minDepth>
    <maxVel>1.0</maxVel>
    <material>Gazebo/Black</material>
  </gazebo>
  <link
    name="fr_steer_link">
    <inertial>
      <origin
        xyz="5.5511E-17 -2.7756E-17 -0.088728"
        rpy="0 0 0" />
      <mass
        value="10" />
      <inertia
        ixx="0.047904"
        ixy="3.1205E-18"
        ixz="-6.2384E-18"
        iyy="0.037562"
        iyz="7.0256E-18"
        izz="0.014192" />
    </inertial>
    <visual>
      <origin
        xyz="0 0 0"
        rpy="0 0 0" />
      <geometry>
        <mesh
          filename="package://car_4ws_4wd/meshes/fr_steer_link.STL" />
      </geometry>
      <material
        name="">
        <color
          rgba="1 0.96078 0.90588 1" />
      </material>
    </visual>
    <collision>
      <origin
        xyz="0 0 0"
        rpy="0 0 0" />
      <geometry>
        <mesh
          filename="package://car_4ws_4wd/meshes/fr_steer_link.STL" />
      </geometry>
    </collision>
  </link>
  <joint
    name="fr_steer_joint"
    type="revolute">
    <origin
      xyz="0.32 -0.235 -0.01"
      rpy="0 0 0" />
    <parent
      link="base_link" />
    <child
      link="fr_steer_link" />
    <axis
      xyz="0 0 1" />
    <limit
      lower="-0.55"
      upper="0.55"
      effort="100"
      velocity="1" />
  </joint>
  <link
    name="fr_drive_link">
    <inertial>
      <origin
        xyz="5.5511E-17 1.3878E-16 -5.5511E-17"
        rpy="0 0 0" />
      <mass
        value="2.1666" />
      <inertia
        ixx="0.010578"
        ixy="-2.2181E-18"
        ixz="-4.0521E-18"
        iyy="0.010578"
        iyz="3.1412E-18"
        izz="0.020276" />
    </inertial>
    <visual>
      <origin
        xyz="0 0 0"
        rpy="0 0 0" />
      <geometry>
        <mesh
          filename="package://car_4ws_4wd/meshes/fr_drive_link.STL" />
      </geometry>
      <material
        name="">
        <color
          rgba="0 0 0 1" />
      </material>
    </visual>
    <collision>
      <origin
        xyz="0 0 0"
        rpy="0 0 0" />
      <geometry>
        <mesh
          filename="package://car_4ws_4wd/meshes/fr_drive_link.STL" />
      </geometry>
    </collision>
  </link>
  <joint
    name="fr_drive_joint"
    type="continuous">
    <origin
      xyz="0 0 -0.16"
      rpy="1.5708 0 0" />
    <parent
      link="fr_steer_link" />
    <child
      link="fr_drive_link" />
    <axis
      xyz="0 0 -1" />
  </joint>
  <gazebo reference="fr_drive_link">
    <mu1>1.0</mu1>
    <mu2>1.0</mu2>
    <kp>1000000.0</kp>
    <kd>100.0</kd>
    <minDepth>0.001</minDepth>
    <maxVel>1.0</maxVel>
    <material>Gazebo/Black</material>
  </gazebo>
  <link
    name="rl_steer_link">
    <inertial>
      <origin
        xyz="5.5511E-17 -8.3267E-17 -0.088728"
        rpy="0 0 0" />
      <mass
        value="10" />
      <inertia
        ixx="0.047904"
        ixy="-8.3959E-19"
        ixz="1.8945E-17"
        iyy="0.037562"
        iyz="-3.449E-17"
        izz="0.014192" />
    </inertial>
    <visual>
      <origin
        xyz="0 0 0"
        rpy="0 0 0" />
      <geometry>
        <mesh
          filename="package://car_4ws_4wd/meshes/rl_steer_link.STL" />
      </geometry>
      <material
        name="">
        <color
          rgba="1 0.96078 0.90588 1" />
      </material>
    </visual>
    <collision>
      <origin
        xyz="0 0 0"
        rpy="0 0 0" />
      <geometry>
        <mesh
          filename="package://car_4ws_4wd/meshes/rl_steer_link.STL" />
      </geometry>
    </collision>
  </link>
  <joint
    name="rl_steer_joint"
    type="revolute">
    <origin
      xyz="-0.32 0.235 -0.01"
      rpy="0 0 0" />
    <parent
      link="base_link" />
    <child
      link="rl_steer_link" />
    <axis
      xyz="0 0 1" />
    <limit
      lower="-0.55"
      upper="0.55"
      effort="100"
      velocity="1" />
  </joint>
  <link
    name="rl_drive_link">
    <inertial>
      <origin
        xyz="1.1102E-16 1.3878E-16 -2.7756E-17"
        rpy="0 0 0" />
      <mass
        value="2.1666" />
      <inertia
        ixx="0.010578"
        ixy="-1.6233E-18"
        ixz="-2.9597E-18"
        iyy="0.010578"
        iyz="1.2936E-17"
        izz="0.020276" />
    </inertial>
    <visual>
      <origin
        xyz="0 0 0"
        rpy="0 0 0" />
      <geometry>
        <mesh
          filename="package://car_4ws_4wd/meshes/rl_drive_link.STL" />
      </geometry>
      <material
        name="">
        <color
          rgba="0 0 0 1" />
      </material>
    </visual>
    <collision>
      <origin
        xyz="0 0 0"
        rpy="0 0 0" />
      <geometry>
        <mesh
          filename="package://car_4ws_4wd/meshes/rl_drive_link.STL" />
      </geometry>
    </collision>
  </link>
  <joint
    name="rl_drive_joint"
    type="continuous">
    <origin
      xyz="0 0 -0.16"
      rpy="1.5708 0 0" />
    <parent
      link="rl_steer_link" />
    <child
      link="rl_drive_link" />
    <axis
      xyz="0 0 -1" />
  </joint>
  <gazebo reference="rl_drive_link">
    <mu1>1.0</mu1>
    <mu2>1.0</mu2>
    <kp>1000000.0</kp>
    <kd>100.0</kd>
    <minDepth>0.001</minDepth>
    <maxVel>1.0</maxVel>
    <material>Gazebo/Black</material>
  </gazebo>
  <link
    name="rr_steer_link">
    <inertial>
      <origin
        xyz="0 -5.5511E-17 -0.088728"
        rpy="0 0 0" />
      <mass
        value="10" />
      <inertia
        ixx="0.047904"
        ixy="2.1797E-18"
        ixz="-6.064E-18"
        iyy="0.037562"
        iyz="-6.0216E-18"
        izz="0.014192" />
    </inertial>
    <visual>
      <origin
        xyz="0 0 0"
        rpy="0 0 0" />
      <geometry>
        <mesh
          filename="package://car_4ws_4wd/meshes/rr_steer_link.STL" />
      </geometry>
      <material
        name="">
        <color
          rgba="1 0.96078 0.90588 1" />
      </material>
    </visual>
    <collision>
      <origin
        xyz="0 0 0"
        rpy="0 0 0" />
      <geometry>
        <mesh
          filename="package://car_4ws_4wd/meshes/rr_steer_link.STL" />
      </geometry>
    </collision>
  </link>
  <joint
    name="rr_steer_joint"
    type="revolute">
    <origin
      xyz="-0.32 -0.235 -0.01"
      rpy="0 0 0" />
    <parent
      link="base_link" />
    <child
      link="rr_steer_link" />
    <axis
      xyz="0 0 1" />
    <limit
      lower="-0.55"
      upper="0.55"
      effort="100"
      velocity="1" />
  </joint>
  <link
    name="rr_drive_link">
    <inertial>
      <origin
        xyz="5.5511E-17 1.3878E-16 2.7756E-17"
        rpy="0 0 0" />
      <mass
        value="2.1666" />
      <inertia
        ixx="0.010578"
        ixy="-2.5405E-18"
        ixz="-3.6714E-18"
        iyy="0.010578"
        iyz="2.8922E-18"
        izz="0.020276" />
    </inertial>
    <visual>
      <origin
        xyz="0 0 0"
        rpy="0 0 0" />
      <geometry>
        <mesh
          filename="package://car_4ws_4wd/meshes/rr_drive_link.STL" />
      </geometry>
      <material
        name="">
        <color
          rgba="0 0 0 1" />
      </material>
    </visual>
    <collision>
      <origin
        xyz="0 0 0"
        rpy="0 0 0" />
      <geometry>
        <mesh
          filename="package://car_4ws_4wd/meshes/rr_drive_link.STL" />
      </geometry>
    </collision>
  </link>
  <joint
    name="rr_drive_joint"
    type="continuous">
    <origin
      xyz="0 0 -0.16"
      rpy="1.5708 0 0" />
    <parent
      link="rr_steer_link" />
    <child
      link="rr_drive_link" />
    <axis
      xyz="0 0 -1" />
  </joint>
  <gazebo reference="rr_drive_link">
    <mu1>1.0</mu1>
    <mu2>1.0</mu2>
    <kp>1000000.0</kp>
    <kd>100.0</kd>
    <minDepth>0.001</minDepth>
    <maxVel>1.0</maxVel>
    <material>Gazebo/Black</material>
  </gazebo>
  <!-- 添加传动装置 -->
  <transmission name="fl_steer_trans">
    <type>transmission_interface/SimpleTransmission</type>
    <joint name="fl_steer_joint">
      <hardwareInterface>hardware_interface/EffortJointInterface</hardwareInterface>
    </joint>
    <actuator name="fl_steer_motor">
      <mechanicalReduction>1</mechanicalReduction>
    </actuator>
  </transmission>

  <transmission name="fr_steer_trans">
    <type>transmission_interface/SimpleTransmission</type>
    <joint name="fr_steer_joint">
      <hardwareInterface>hardware_interface/EffortJointInterface</hardwareInterface>
    </joint>
    <actuator name="fr_steer_motor">
      <mechanicalReduction>1</mechanicalReduction>
    </actuator>
  </transmission>

  <transmission name="rl_steer_trans">
    <type>transmission_interface/SimpleTransmission</type>
    <joint name="rl_steer_joint">
      <hardwareInterface>hardware_interface/EffortJointInterface</hardwareInterface>
    </joint>
    <actuator name="rl_steer_motor">
      <mechanicalReduction>1</mechanicalReduction>
    </actuator>
  </transmission>

  <transmission name="rr_steer_trans">
    <type>transmission_interface/SimpleTransmission</type>
    <joint name="rr_steer_joint">
      <hardwareInterface>hardware_interface/EffortJointInterface</hardwareInterface>
    </joint>
    <actuator name="rr_steer_motor">
      <mechanicalReduction>1</mechanicalReduction>
    </actuator>
  </transmission>

  <transmission name="fl_drive_trans">
    <type>transmission_interface/SimpleTransmission</type>
    <joint name="fl_drive_joint">
      <hardwareInterface>hardware_interface/VelocityJointInterface</hardwareInterface>
    </joint>
    <actuator name="fl_drive_motor">
      <mechanicalReduction>1</mechanicalReduction>
    </actuator>
  </transmission>

  <transmission name="fr_drive_trans">
    <type>transmission_interface/SimpleTransmission</type>
    <joint name="fr_drive_joint">
      <hardwareInterface>hardware_interface/VelocityJointInterface</hardwareInterface>
    </joint>
    <actuator name="fr_drive_motor">
      <mechanicalReduction>1</mechanicalReduction>
    </actuator>
  </transmission>

  <transmission name="rl_drive_trans">
    <type>transmission_interface/SimpleTransmission</type>
    <joint name="rl_drive_joint">
      <hardwareInterface>hardware_interface/VelocityJointInterface</hardwareInterface>
    </joint>
    <actuator name="rl_drive_motor">
      <mechanicalReduction>1</mechanicalReduction>
    </actuator>
  </transmission>

  <transmission name="rr_drive_trans">
    <type>transmission_interface/SimpleTransmission</type>
    <joint name="rr_drive_joint">
      <hardwareInterface>hardware_interface/VelocityJointInterface</hardwareInterface>
    </joint>
    <actuator name="rr_drive_motor">
      <mechanicalReduction>1</mechanicalReduction>
    </actuator>
  </transmission>
  <!-- 添加 Gazebo ROS Control 插件 -->
  <gazebo>
    <plugin name="gazebo_ros_control" filename="libgazebo_ros_control.so">
      <robotNamespace>/car_4ws_4wd</robotNamespace>
    </plugin>
  </gazebo>

</robot>